<?xml version="1.0"?>
<robot xmlns:xacro="http://www.ros.org/wiki/xacro">

	<xacro:include filename="inertial_macros.xacro" />
    
    <material name="orange">
		<color rgba="1 0.3 0.1 1" />
    </material>
    
    <material name="black">
		<color rgba="0 0 0 1" />
    </material>
    
    <!-- BASE_LINK -->
    
    <link name="tb2_base_link">
    </link>

	<link name="tb2_base_footprint">
	</link>

	<joint name="tb2_base_footprint_joint" type="fixed">
		<parent link="tb2_base_footprint" />
		<child  link="tb2_base_link" />
		<origin xyz="0 0 0" rpy="0 0 0" />
	</joint>
    
    <!-- CHASSIS -->
    
    <link name="tb2_chassis">
    	<visual>
			<origin xyz="0 0 0" />
    	    <geometry>
				<cylinder radius="0.177" length="0.420" />
    	    </geometry>
			<material name="orange" />
    	</visual>
    	<collision>
			<origin xyz="0 0 0" />
    	    <geometry>
				<cylinder radius="0.177" length="0.420" />
    	    </geometry>
    	</collision>
    	<xacro:inertial_cylinder mass="0.5" length="0.420" radius="0.177">
			<origin xyz="0 0 0" rpy="0 0 0" />
    	</xacro:inertial_cylinder>
    </link>
    
    <gazebo reference="tb2_chassis">
        <material>Gazebo/Orange</material>
    </gazebo>
    
    <joint name="tb2_chassis_joint" type="fixed">
		<parent link="tb2_base_link" />
		<child link="tb2_chassis" />
		<origin xyz="0 0 0" />
    </joint>
    
    <!-- LEFT_WHEEL -->
    
    <link name="tb2_left_wheel">
    	<visual>
    	    <geometry>
				<cylinder radius="0.04" length="0.04" />
    	    </geometry>
			<material name="black" />
    	</visual>
    	<collision>
    	    <geometry>
				<cylinder radius="0.04" length="0.04" />
    	    </geometry>
    	</collision>
    	<xacro:inertial_cylinder mass="0.1" length="0.04" radius="0.04">
			<origin xyz="0 0 0" rpy="0 0 0" />
    	</xacro:inertial_cylinder>
    </link>
    
    <gazebo reference="tb2_left_wheel">
        <material>Gazebo/Black</material>
    </gazebo>
    
    <joint name="tb2_left_wheel_joint" type="continuous">
		<parent link="tb2_chassis" />
		<child link="tb2_left_wheel" />
		<origin xyz="0 0.157 -0.210" rpy="-${pi/2} 0 0" />
		<axis xyz="0 0 1" />
    </joint>
    
    <!-- RIGHT_WHEEL -->
    
    <link name="tb2_right_wheel">
    	<visual>
    	    <geometry>
				<cylinder radius="0.04" length="0.04" />
    	    </geometry>
			<material name="black" />
    	</visual>
    	<collision>
    	    <geometry>
				<cylinder radius="0.04" length="0.04" />
    	    </geometry>
    	</collision>
    	<xacro:inertial_cylinder mass="0.1" length="0.04" radius="0.04">
			<origin xyz="0 0 0" rpy="0 0 0" />
    	</xacro:inertial_cylinder>
    </link>
    
    <gazebo reference="tb2_right_wheel">
        <material>Gazebo/Black</material>
    </gazebo>
    
    <joint name="tb2_right_wheel_joint" type="continuous">
		<parent link="tb2_chassis" />
		<child link="tb2_right_wheel" />
		<origin xyz="0 -0.157 -0.210" rpy="${pi/2} 0 0" />
		<axis xyz="0 0 -1" />
    </joint>
    
    <!-- CASTER WHEEL -->
    
    <link name="tb2_caster_wheel_forward">
        <visual>
            <geometry>
				<sphere radius="0.04" />
    	    </geometry>
			<material name="black" />
    	</visual>
    	<collision>
            <geometry>
				<sphere radius="0.04" />
    	    </geometry>
    	</collision>
    	<xacro:inertial_sphere mass="0.1" radius="0.04">
			<origin xyz="0 0 0" rpy="0 0 0" />
    	</xacro:inertial_sphere>
    </link>
    
    <gazebo reference="tb2_caster_wheel_forward">
        <material>Gazebo/Black</material>
		<mu1 value="0.001" />
		<mu2 value="0.001" />
    </gazebo>
    
    <joint name="tb2_caster_wheel_forward_joint" type="fixed">
		<parent link="tb2_chassis" />
		<child link="tb2_caster_wheel_forward" />
		<origin xyz="0.12 0 -0.210" />
    </joint>

	<link name="tb2_caster_wheel_backward">
		<visual>
			<geometry>
				<sphere radius="0.04" />
			</geometry>
			<material name="black" />
		</visual>
		<collision>
			<geometry>
				<sphere radius="0.04" />
			</geometry>
		</collision>
		<xacro:inertial_sphere mass="0.1" radius="0.04">
			<origin xyz="0 0 0" rpy="0 0 0" />
		</xacro:inertial_sphere>
	</link>

	<gazebo reference="tb2_caster_wheel_backward">
		<material>Gazebo/Black</material>
		<mu1 value="0.001" />
		<mu2 value="0.001" />
	</gazebo>

	<joint name="tb2_caster_wheel_backward_joint" type="fixed">
		<parent link="tb2_chassis" />
		<child link="tb2_caster_wheel_backward" />
		<origin xyz="-0.12 0 -0.210" />
	</joint>

</robot>
